--------- 16:26:08 ---------
Ref URL: https://projectv.com/AwaitingDelivery
Host: projectv.com
URL: /AwaitingDelivery/AddBill
IP: 127.0.0.1
Error: Validation failed for one or more entities. See 'EntityValidationErrors' property for more details.
Source: EntityFramework
Trace:    at System.Data.Entity.Internal.InternalContext.SaveChangesAsync(CancellationToken cancellationToken)
   at System.Data.Entity.Internal.LazyInternalContext.SaveChangesAsync(CancellationToken cancellationToken)
   at System.Data.Entity.DbContext.SaveChangesAsync(CancellationToken cancellationToken)
   at System.Data.Entity.DbContext.SaveChangesAsync()
   at Library.UnitOfWork.Repository`1.SaveAsync() in C:\Tfs\ProjectV\Library\UnitOfWork\Repository.cs:line 781
   at Cms.Controllers.AwaitingDeliveryController.<AddBill>d__5.MoveNext() in C:\Tfs\ProjectV\Cms\Controllers\AwaitingDeliveryController.cs:line 725
--- End of stack trace from previous location where exception was thrown ---
   at System.Runtime.ExceptionServices.ExceptionDispatchInfo.Throw()
   at Cms.Controllers.AwaitingDeliveryController.<AddBill>d__5.MoveNext() in C:\Tfs\ProjectV\Cms\Controllers\AwaitingDeliveryController.cs:line 906
--- End of stack trace from previous location where exception was thrown ---
   at System.Runtime.CompilerServices.TaskAwaiter.ThrowForNonSuccess(Task task)
   at System.Runtime.CompilerServices.TaskAwaiter.HandleNonSuccessAndDebuggerNotification(Task task)
   at System.Web.Mvc.Async.TaskAsyncActionDescriptor.EndExecute(IAsyncResult asyncResult)
   at System.Web.Mvc.Async.AsyncControllerActionInvoker.<>c__DisplayClass37.<BeginInvokeAsynchronousActionMethod>b__36(IAsyncResult asyncResult)
   at System.Web.Mvc.Async.AsyncControllerActionInvoker.EndInvokeActionMethod(IAsyncResult asyncResult)
   at System.Web.Mvc.Async.AsyncControllerActionInvoker.AsyncInvocationWithFilters.<InvokeActionMethodFilterAsynchronouslyRecursive>b__3d()
   at System.Web.Mvc.Async.AsyncControllerActionInvoker.AsyncInvocationWithFilters.<>c__DisplayClass46.<InvokeActionMethodFilterAsynchronouslyRecursive>b__3f()
   at System.Web.Mvc.Async.AsyncControllerActionInvoker.EndInvokeActionMethodWithFilters(IAsyncResult asyncResult)
   at System.Web.Mvc.Async.AsyncControllerActionInvoker.<>c__DisplayClass21.<>c__DisplayClass2b.<BeginInvokeAction>b__1c()
   at System.Web.Mvc.Async.AsyncControllerActionInvoker.<>c__DisplayClass21.<BeginInvokeAction>b__1e(IAsyncResult asyncResult)
InnerException : 
GetBaseException : System.Data.Entity.Validation.DbEntityValidationException: Validation failed for one or more entities. See 'EntityValidationErrors' property for more details.
   at System.Data.Entity.Internal.InternalContext.SaveChangesAsync(CancellationToken cancellationToken)
   at System.Data.Entity.Internal.LazyInternalContext.SaveChangesAsync(CancellationToken cancellationToken)
   at System.Data.Entity.DbContext.SaveChangesAsync(CancellationToken cancellationToken)
   at System.Data.Entity.DbContext.SaveChangesAsync()
   at Library.UnitOfWork.Repository`1.SaveAsync() in C:\Tfs\ProjectV\Library\UnitOfWork\Repository.cs:line 781
   at Cms.Controllers.AwaitingDeliveryController.<AddBill>d__5.MoveNext() in C:\Tfs\ProjectV\Cms\Controllers\AwaitingDeliveryController.cs:line 725
--- End of stack trace from previous location where exception was thrown ---
   at System.Runtime.ExceptionServices.ExceptionDispatchInfo.Throw()
   at Cms.Controllers.AwaitingDeliveryController.<AddBill>d__5.MoveNext() in C:\Tfs\ProjectV\Cms\Controllers\AwaitingDeliveryController.cs:line 906
--- End of stack trace from previous location where exception was thrown ---
   at System.Runtime.CompilerServices.TaskAwaiter.ThrowForNonSuccess(Task task)
   at System.Runtime.CompilerServices.TaskAwaiter.HandleNonSuccessAndDebuggerNotification(Task task)
   at System.Web.Mvc.Async.TaskAsyncActionDescriptor.EndExecute(IAsyncResult asyncResult)
   at System.Web.Mvc.Async.AsyncControllerActionInvoker.<>c__DisplayClass37.<BeginInvokeAsynchronousActionMethod>b__36(IAsyncResult asyncResult)
   at System.Web.Mvc.Async.AsyncControllerActionInvoker.EndInvokeActionMethod(IAsyncResult asyncResult)
   at System.Web.Mvc.Async.AsyncControllerActionInvoker.AsyncInvocationWithFilters.<InvokeActionMethodFilterAsynchronouslyRecursive>b__3d()
   at System.Web.Mvc.Async.AsyncControllerActionInvoker.AsyncInvocationWithFilters.<>c__DisplayClass46.<InvokeActionMethodFilterAsynchronouslyRecursive>b__3f()
   at System.Web.Mvc.Async.AsyncControllerActionInvoker.EndInvokeActionMethodWithFilters(IAsyncResult asyncResult)
   at System.Web.Mvc.Async.AsyncControllerActionInvoker.<>c__DisplayClass21.<>c__DisplayClass2b.<BeginInvokeAction>b__1c()
   at System.Web.Mvc.Async.AsyncControllerActionInvoker.<>c__DisplayClass21.<BeginInvokeAction>b__1e(IAsyncResult asyncResult)
TargetSite : System.Threading.Tasks.Task`1[System.Int32] SaveChangesAsync(System.Threading.CancellationToken)
--------- 16:29:19 ---------
Ref URL: https://projectv.com/AwaitingDelivery
Host: projectv.com
URL: /AwaitingDelivery/AddBill
IP: 127.0.0.1
Error: Validation failed for one or more entities. See 'EntityValidationErrors' property for more details.
Source: EntityFramework
Trace:    at System.Data.Entity.Internal.InternalContext.SaveChangesAsync(CancellationToken cancellationToken)
   at System.Data.Entity.Internal.LazyInternalContext.SaveChangesAsync(CancellationToken cancellationToken)
   at System.Data.Entity.DbContext.SaveChangesAsync(CancellationToken cancellationToken)
   at System.Data.Entity.DbContext.SaveChangesAsync()
   at Library.UnitOfWork.Repository`1.SaveAsync() in C:\Tfs\ProjectV\Library\UnitOfWork\Repository.cs:line 781
   at Cms.Controllers.AwaitingDeliveryController.<AddBill>d__5.MoveNext() in C:\Tfs\ProjectV\Cms\Controllers\AwaitingDeliveryController.cs:line 725
--- End of stack trace from previous location where exception was thrown ---
   at System.Runtime.ExceptionServices.ExceptionDispatchInfo.Throw()
   at Cms.Controllers.AwaitingDeliveryController.<AddBill>d__5.MoveNext() in C:\Tfs\ProjectV\Cms\Controllers\AwaitingDeliveryController.cs:line 906
--- End of stack trace from previous location where exception was thrown ---
   at System.Runtime.CompilerServices.TaskAwaiter.ThrowForNonSuccess(Task task)
   at System.Runtime.CompilerServices.TaskAwaiter.HandleNonSuccessAndDebuggerNotification(Task task)
   at System.Web.Mvc.Async.TaskAsyncActionDescriptor.EndExecute(IAsyncResult asyncResult)
   at System.Web.Mvc.Async.AsyncControllerActionInvoker.<>c__DisplayClass37.<BeginInvokeAsynchronousActionMethod>b__36(IAsyncResult asyncResult)
   at System.Web.Mvc.Async.AsyncControllerActionInvoker.EndInvokeActionMethod(IAsyncResult asyncResult)
   at System.Web.Mvc.Async.AsyncControllerActionInvoker.AsyncInvocationWithFilters.<InvokeActionMethodFilterAsynchronouslyRecursive>b__3d()
   at System.Web.Mvc.Async.AsyncControllerActionInvoker.AsyncInvocationWithFilters.<>c__DisplayClass46.<InvokeActionMethodFilterAsynchronouslyRecursive>b__3f()
   at System.Web.Mvc.Async.AsyncControllerActionInvoker.EndInvokeActionMethodWithFilters(IAsyncResult asyncResult)
   at System.Web.Mvc.Async.AsyncControllerActionInvoker.<>c__DisplayClass21.<>c__DisplayClass2b.<BeginInvokeAction>b__1c()
   at System.Web.Mvc.Async.AsyncControllerActionInvoker.<>c__DisplayClass21.<BeginInvokeAction>b__1e(IAsyncResult asyncResult)
InnerException : 
GetBaseException : System.Data.Entity.Validation.DbEntityValidationException: Validation failed for one or more entities. See 'EntityValidationErrors' property for more details.
   at System.Data.Entity.Internal.InternalContext.SaveChangesAsync(CancellationToken cancellationToken)
   at System.Data.Entity.Internal.LazyInternalContext.SaveChangesAsync(CancellationToken cancellationToken)
   at System.Data.Entity.DbContext.SaveChangesAsync(CancellationToken cancellationToken)
   at System.Data.Entity.DbContext.SaveChangesAsync()
   at Library.UnitOfWork.Repository`1.SaveAsync() in C:\Tfs\ProjectV\Library\UnitOfWork\Repository.cs:line 781
   at Cms.Controllers.AwaitingDeliveryController.<AddBill>d__5.MoveNext() in C:\Tfs\ProjectV\Cms\Controllers\AwaitingDeliveryController.cs:line 725
--- End of stack trace from previous location where exception was thrown ---
   at System.Runtime.ExceptionServices.ExceptionDispatchInfo.Throw()
   at Cms.Controllers.AwaitingDeliveryController.<AddBill>d__5.MoveNext() in C:\Tfs\ProjectV\Cms\Controllers\AwaitingDeliveryController.cs:line 906
--- End of stack trace from previous location where exception was thrown ---
   at System.Runtime.CompilerServices.TaskAwaiter.ThrowForNonSuccess(Task task)
   at System.Runtime.CompilerServices.TaskAwaiter.HandleNonSuccessAndDebuggerNotification(Task task)
   at System.Web.Mvc.Async.TaskAsyncActionDescriptor.EndExecute(IAsyncResult asyncResult)
   at System.Web.Mvc.Async.AsyncControllerActionInvoker.<>c__DisplayClass37.<BeginInvokeAsynchronousActionMethod>b__36(IAsyncResult asyncResult)
   at System.Web.Mvc.Async.AsyncControllerActionInvoker.EndInvokeActionMethod(IAsyncResult asyncResult)
   at System.Web.Mvc.Async.AsyncControllerActionInvoker.AsyncInvocationWithFilters.<InvokeActionMethodFilterAsynchronouslyRecursive>b__3d()
   at System.Web.Mvc.Async.AsyncControllerActionInvoker.AsyncInvocationWithFilters.<>c__DisplayClass46.<InvokeActionMethodFilterAsynchronouslyRecursive>b__3f()
   at System.Web.Mvc.Async.AsyncControllerActionInvoker.EndInvokeActionMethodWithFilters(IAsyncResult asyncResult)
   at System.Web.Mvc.Async.AsyncControllerActionInvoker.<>c__DisplayClass21.<>c__DisplayClass2b.<BeginInvokeAction>b__1c()
   at System.Web.Mvc.Async.AsyncControllerActionInvoker.<>c__DisplayClass21.<BeginInvokeAction>b__1e(IAsyncResult asyncResult)
TargetSite : System.Threading.Tasks.Task`1[System.Int32] SaveChangesAsync(System.Threading.CancellationToken)
--------- 17:00:56 ---------
Ref URL: https://projectv.com/TrackingPackage
Host: projectv.com
URL: /Package/Transfer
IP: 127.0.0.1
Error: The required anti-forgery form field "__RequestVerificationToken" is not present.
Source: System.Web.WebPages
Trace:    at System.Web.Helpers.AntiXsrf.TokenValidator.ValidateTokens(HttpContextBase httpContext, IIdentity identity, AntiForgeryToken sessionToken, AntiForgeryToken fieldToken)
   at System.Web.Helpers.AntiXsrf.AntiForgeryWorker.Validate(HttpContextBase httpContext)
   at System.Web.Mvc.ControllerActionInvoker.InvokeAuthorizationFilters(ControllerContext controllerContext, IList`1 filters, ActionDescriptor actionDescriptor)
   at System.Web.Mvc.Async.AsyncControllerActionInvoker.<>c__DisplayClass21.<BeginInvokeAction>b__19(AsyncCallback asyncCallback, Object asyncState)
InnerException : 
GetBaseException : System.Web.Mvc.HttpAntiForgeryException (0x80004005): The required anti-forgery form field "__RequestVerificationToken" is not present.
   at System.Web.Helpers.AntiXsrf.TokenValidator.ValidateTokens(HttpContextBase httpContext, IIdentity identity, AntiForgeryToken sessionToken, AntiForgeryToken fieldToken)
   at System.Web.Helpers.AntiXsrf.AntiForgeryWorker.Validate(HttpContextBase httpContext)
   at System.Web.Mvc.ControllerActionInvoker.InvokeAuthorizationFilters(ControllerContext controllerContext, IList`1 filters, ActionDescriptor actionDescriptor)
   at System.Web.Mvc.Async.AsyncControllerActionInvoker.<>c__DisplayClass21.<BeginInvokeAction>b__19(AsyncCallback asyncCallback, Object asyncState)
TargetSite : Void ValidateTokens(System.Web.HttpContextBase, System.Security.Principal.IIdentity, System.Web.Helpers.AntiXsrf.AntiForgeryToken, System.Web.Helpers.AntiXsrf.AntiForgeryToken)
--------- 21:40:40 ---------
Ref URL: https://projectv.com/
Host: projectv.com
URL: /TrackingPackage
IP: 127.0.0.1
Error: The underlying provider failed on Open.
Source: EntityFramework
Trace:    at System.Data.Entity.Core.EntityClient.EntityConnection.Open()
   at System.Data.Entity.Core.Objects.ObjectContext.EnsureConnection(Boolean shouldMonitorTransactions)
   at System.Data.Entity.Core.Objects.ObjectContext.ExecuteInTransaction[T](Func`1 func, IDbExecutionStrategy executionStrategy, Boolean startLocalTransaction, Boolean releaseConnectionOnSuccess)
   at System.Data.Entity.Core.Objects.ObjectQuery`1.<>c__DisplayClass7.<GetResults>b__5()
   at System.Data.Entity.SqlServer.DefaultSqlExecutionStrategy.Execute[TResult](Func`1 operation)
   at System.Data.Entity.Core.Objects.ObjectQuery`1.GetResults(Nullable`1 forMergeOption)
   at System.Data.Entity.Core.Objects.ObjectQuery`1.<System.Collections.Generic.IEnumerable<T>.GetEnumerator>b__0()
   at System.Data.Entity.Internal.LazyEnumerator`1.MoveNext()
   at System.Linq.Enumerable.Single[TSource](IEnumerable`1 source)
   at Library.DbContext.Repositories.NotifyRealTimeRepository.GetNotifySystemByToUserId(String keyword, Int32 userId, Nullable`1 isRead, Nullable`1 type, Int32 currentPage, Int32 recordPerPage, Int32& totalRecord) in C:\Tfs\ProjectV\Library\DbContext\Repositories\NotifyRealTimeRepository.cs:line 29
   at Cms.Attributes.LogTrackerAttribute.OnActionExecuting(ActionExecutingContext filterContext) in C:\Tfs\ProjectV\Cms\Attributes\LogTrackerAttribute.cs:line 91
   at System.Web.Mvc.Async.AsyncControllerActionInvoker.AsyncInvocationWithFilters.InvokeActionMethodFilterAsynchronouslyRecursive(Int32 filterIndex)
   at System.Web.Mvc.Async.AsyncControllerActionInvoker.AsyncInvocationWithFilters.InvokeActionMethodFilterAsynchronouslyRecursive(Int32 filterIndex)
   at System.Web.Mvc.Async.AsyncControllerActionInvoker.<>c__DisplayClass33.<BeginInvokeActionMethodWithFilters>b__31(AsyncCallback asyncCallback, Object asyncState)
   at System.Web.Mvc.Async.AsyncResultWrapper.WrappedAsyncResultBase`1.Begin(AsyncCallback callback, Object state, Int32 timeout)
   at System.Web.Mvc.Async.AsyncControllerActionInvoker.BeginInvokeActionMethodWithFilters(ControllerContext controllerContext, IList`1 filters, ActionDescriptor actionDescriptor, IDictionary`2 parameters, AsyncCallback callback, Object state)
   at System.Web.Mvc.Async.AsyncControllerActionInvoker.<>c__DisplayClass21.<BeginInvokeAction>b__19(AsyncCallback asyncCallback, Object asyncState)
InnerException : System.Data.SqlClient.SqlException (0x80131904): A network-related or instance-specific error occurred while establishing a connection to SQL Server. The server was not found or was not accessible. Verify that the instance name is correct and that SQL Server is configured to allow remote connections. (provider: Named Pipes Provider, error: 40 - Could not open a connection to SQL Server) ---> System.ComponentModel.Win32Exception (0x80004005): The network path was not found
   at System.Data.SqlClient.SqlInternalConnectionTds..ctor(DbConnectionPoolIdentity identity, SqlConnectionString connectionOptions, SqlCredential credential, Object providerInfo, String newPassword, SecureString newSecurePassword, Boolean redirectedUserInstance, SqlConnectionString userConnectionOptions, SessionData reconnectSessionData, DbConnectionPool pool, String accessToken, Boolean applyTransientFaultHandling)
   at System.Data.SqlClient.SqlConnectionFactory.CreateConnection(DbConnectionOptions options, DbConnectionPoolKey poolKey, Object poolGroupProviderInfo, DbConnectionPool pool, DbConnection owningConnection, DbConnectionOptions userOptions)
   at System.Data.ProviderBase.DbConnectionFactory.CreatePooledConnection(DbConnectionPool pool, DbConnection owningObject, DbConnectionOptions options, DbConnectionPoolKey poolKey, DbConnectionOptions userOptions)
   at System.Data.ProviderBase.DbConnectionPool.CreateObject(DbConnection owningObject, DbConnectionOptions userOptions, DbConnectionInternal oldConnection)
   at System.Data.ProviderBase.DbConnectionPool.UserCreateRequest(DbConnection owningObject, DbConnectionOptions userOptions, DbConnectionInternal oldConnection)
   at System.Data.ProviderBase.DbConnectionPool.TryGetConnection(DbConnection owningObject, UInt32 waitForMultipleObjectsTimeout, Boolean allowCreate, Boolean onlyOneCheckConnection, DbConnectionOptions userOptions, DbConnectionInternal& connection)
   at System.Data.ProviderBase.DbConnectionPool.TryGetConnection(DbConnection owningObject, TaskCompletionSource`1 retry, DbConnectionOptions userOptions, DbConnectionInternal& connection)
   at System.Data.ProviderBase.DbConnectionFactory.TryGetConnection(DbConnection owningConnection, TaskCompletionSource`1 retry, DbConnectionOptions userOptions, DbConnectionInternal oldConnection, DbConnectionInternal& connection)
   at System.Data.ProviderBase.DbConnectionInternal.TryOpenConnectionInternal(DbConnection outerConnection, DbConnectionFactory connectionFactory, TaskCompletionSource`1 retry, DbConnectionOptions userOptions)
   at System.Data.SqlClient.SqlConnection.TryOpenInner(TaskCompletionSource`1 retry)
   at System.Data.SqlClient.SqlConnection.TryOpen(TaskCompletionSource`1 retry)
   at System.Data.SqlClient.SqlConnection.Open()
   at System.Data.Entity.Infrastructure.Interception.InternalDispatcher`1.Dispatch[TTarget,TInterceptionContext](TTarget target, Action`2 operation, TInterceptionContext interceptionContext, Action`3 executing, Action`3 executed)
   at System.Data.Entity.Infrastructure.Interception.DbConnectionDispatcher.Open(DbConnection connection, DbInterceptionContext interceptionContext)
   at System.Data.Entity.SqlServer.DefaultSqlExecutionStrategy.<>c__DisplayClass1.<Execute>b__0()
   at System.Data.Entity.SqlServer.DefaultSqlExecutionStrategy.Execute[TResult](Func`1 operation)
   at System.Data.Entity.Core.EntityClient.EntityConnection.Open()
ClientConnectionId:00000000-0000-0000-0000-000000000000
Error Number:53,State:0,Class:20
GetBaseException : System.ComponentModel.Win32Exception (0x80004005): The network path was not found
TargetSite : Void Open()
--------- 21:40:40 ---------
Ref URL: https://projectv.com/
Host: projectv.com
URL: /Purchase/Order
IP: 127.0.0.1
Error: The underlying provider failed on Open.
Source: EntityFramework
Trace:    at System.Data.Entity.Core.EntityClient.EntityConnection.Open()
   at System.Data.Entity.Core.Objects.ObjectContext.EnsureConnection(Boolean shouldMonitorTransactions)
   at System.Data.Entity.Core.Objects.ObjectContext.ExecuteInTransaction[T](Func`1 func, IDbExecutionStrategy executionStrategy, Boolean startLocalTransaction, Boolean releaseConnectionOnSuccess)
   at System.Data.Entity.Core.Objects.ObjectQuery`1.<>c__DisplayClass7.<GetResults>b__5()
   at System.Data.Entity.SqlServer.DefaultSqlExecutionStrategy.Execute[TResult](Func`1 operation)
   at System.Data.Entity.Core.Objects.ObjectQuery`1.GetResults(Nullable`1 forMergeOption)
   at System.Data.Entity.Core.Objects.ObjectQuery`1.<System.Collections.Generic.IEnumerable<T>.GetEnumerator>b__0()
   at System.Data.Entity.Internal.LazyEnumerator`1.MoveNext()
   at System.Linq.Enumerable.Single[TSource](IEnumerable`1 source)
   at Library.DbContext.Repositories.NotifyRealTimeRepository.GetNotifySystemByToUserId(String keyword, Int32 userId, Nullable`1 isRead, Nullable`1 type, Int32 currentPage, Int32 recordPerPage, Int32& totalRecord) in C:\Tfs\ProjectV\Library\DbContext\Repositories\NotifyRealTimeRepository.cs:line 29
   at Cms.Attributes.LogTrackerAttribute.OnActionExecuting(ActionExecutingContext filterContext) in C:\Tfs\ProjectV\Cms\Attributes\LogTrackerAttribute.cs:line 91
   at System.Web.Mvc.Async.AsyncControllerActionInvoker.AsyncInvocationWithFilters.InvokeActionMethodFilterAsynchronouslyRecursive(Int32 filterIndex)
   at System.Web.Mvc.Async.AsyncControllerActionInvoker.AsyncInvocationWithFilters.InvokeActionMethodFilterAsynchronouslyRecursive(Int32 filterIndex)
   at System.Web.Mvc.Async.AsyncControllerActionInvoker.<>c__DisplayClass33.<BeginInvokeActionMethodWithFilters>b__31(AsyncCallback asyncCallback, Object asyncState)
   at System.Web.Mvc.Async.AsyncResultWrapper.WrappedAsyncResultBase`1.Begin(AsyncCallback callback, Object state, Int32 timeout)
   at System.Web.Mvc.Async.AsyncControllerActionInvoker.BeginInvokeActionMethodWithFilters(ControllerContext controllerContext, IList`1 filters, ActionDescriptor actionDescriptor, IDictionary`2 parameters, AsyncCallback callback, Object state)
   at System.Web.Mvc.Async.AsyncControllerActionInvoker.<>c__DisplayClass21.<BeginInvokeAction>b__19(AsyncCallback asyncCallback, Object asyncState)
InnerException : System.Data.SqlClient.SqlException (0x80131904): A network-related or instance-specific error occurred while establishing a connection to SQL Server. The server was not found or was not accessible. Verify that the instance name is correct and that SQL Server is configured to allow remote connections. (provider: Named Pipes Provider, error: 40 - Could not open a connection to SQL Server) ---> System.ComponentModel.Win32Exception (0x80004005): The network path was not found
   at System.Data.ProviderBase.DbConnectionPool.UserCreateRequest(DbConnection owningObject, DbConnectionOptions userOptions, DbConnectionInternal oldConnection)
   at System.Data.ProviderBase.DbConnectionPool.TryGetConnection(DbConnection owningObject, UInt32 waitForMultipleObjectsTimeout, Boolean allowCreate, Boolean onlyOneCheckConnection, DbConnectionOptions userOptions, DbConnectionInternal& connection)
   at System.Data.ProviderBase.DbConnectionPool.TryGetConnection(DbConnection owningObject, TaskCompletionSource`1 retry, DbConnectionOptions userOptions, DbConnectionInternal& connection)
   at System.Data.ProviderBase.DbConnectionFactory.TryGetConnection(DbConnection owningConnection, TaskCompletionSource`1 retry, DbConnectionOptions userOptions, DbConnectionInternal oldConnection, DbConnectionInternal& connection)
   at System.Data.ProviderBase.DbConnectionInternal.TryOpenConnectionInternal(DbConnection outerConnection, DbConnectionFactory connectionFactory, TaskCompletionSource`1 retry, DbConnectionOptions userOptions)
   at System.Data.SqlClient.SqlConnection.TryOpenInner(TaskCompletionSource`1 retry)
   at System.Data.SqlClient.SqlConnection.TryOpen(TaskCompletionSource`1 retry)
   at System.Data.SqlClient.SqlConnection.Open()
   at System.Data.Entity.Infrastructure.Interception.InternalDispatcher`1.Dispatch[TTarget,TInterceptionContext](TTarget target, Action`2 operation, TInterceptionContext interceptionContext, Action`3 executing, Action`3 executed)
   at System.Data.Entity.Infrastructure.Interception.DbConnectionDispatcher.Open(DbConnection connection, DbInterceptionContext interceptionContext)
   at System.Data.Entity.SqlServer.DefaultSqlExecutionStrategy.<>c__DisplayClass1.<Execute>b__0()
   at System.Data.Entity.SqlServer.DefaultSqlExecutionStrategy.Execute[TResult](Func`1 operation)
   at System.Data.Entity.Core.EntityClient.EntityConnection.Open()
ClientConnectionId:00000000-0000-0000-0000-000000000000
Error Number:53,State:0,Class:20
GetBaseException : System.ComponentModel.Win32Exception (0x80004005): The network path was not found
TargetSite : Void Open()
--------- 21:40:41 ---------
Ref URL: https://projectv.com/accountant
Host: projectv.com
URL: /error/no-permission?permission=Xem&pages=Theo%20d%c3%b5i%20c%c3%b4ng%20n%e1%bb%a3%20%c4%91%c6%a1n%20h%c3%a0ng
IP: 127.0.0.1
Error: The underlying provider failed on Open.
Source: EntityFramework
Trace:    at System.Data.Entity.Core.EntityClient.EntityConnection.Open()
   at System.Data.Entity.Core.Objects.ObjectContext.EnsureConnection(Boolean shouldMonitorTransactions)
   at System.Data.Entity.Core.Objects.ObjectContext.ExecuteInTransaction[T](Func`1 func, IDbExecutionStrategy executionStrategy, Boolean startLocalTransaction, Boolean releaseConnectionOnSuccess)
   at System.Data.Entity.Core.Objects.ObjectQuery`1.<>c__DisplayClass7.<GetResults>b__5()
   at System.Data.Entity.SqlServer.DefaultSqlExecutionStrategy.Execute[TResult](Func`1 operation)
   at System.Data.Entity.Core.Objects.ObjectQuery`1.GetResults(Nullable`1 forMergeOption)
   at System.Data.Entity.Core.Objects.ObjectQuery`1.<System.Collections.Generic.IEnumerable<T>.GetEnumerator>b__0()
   at System.Data.Entity.Internal.LazyEnumerator`1.MoveNext()
   at System.Linq.Enumerable.Single[TSource](IEnumerable`1 source)
   at Library.DbContext.Repositories.NotifyRealTimeRepository.GetNotifySystemByToUserId(String keyword, Int32 userId, Nullable`1 isRead, Nullable`1 type, Int32 currentPage, Int32 recordPerPage, Int32& totalRecord) in C:\Tfs\ProjectV\Library\DbContext\Repositories\NotifyRealTimeRepository.cs:line 29
   at Cms.Attributes.LogTrackerAttribute.OnActionExecuting(ActionExecutingContext filterContext) in C:\Tfs\ProjectV\Cms\Attributes\LogTrackerAttribute.cs:line 91
   at System.Web.Mvc.Async.AsyncControllerActionInvoker.AsyncInvocationWithFilters.InvokeActionMethodFilterAsynchronouslyRecursive(Int32 filterIndex)
   at System.Web.Mvc.Async.AsyncControllerActionInvoker.AsyncInvocationWithFilters.InvokeActionMethodFilterAsynchronouslyRecursive(Int32 filterIndex)
   at System.Web.Mvc.Async.AsyncControllerActionInvoker.<>c__DisplayClass33.<BeginInvokeActionMethodWithFilters>b__31(AsyncCallback asyncCallback, Object asyncState)
   at System.Web.Mvc.Async.AsyncResultWrapper.WrappedAsyncResultBase`1.Begin(AsyncCallback callback, Object state, Int32 timeout)
   at System.Web.Mvc.Async.AsyncControllerActionInvoker.BeginInvokeActionMethodWithFilters(ControllerContext controllerContext, IList`1 filters, ActionDescriptor actionDescriptor, IDictionary`2 parameters, AsyncCallback callback, Object state)
   at System.Web.Mvc.Async.AsyncControllerActionInvoker.<>c__DisplayClass21.<BeginInvokeAction>b__19(AsyncCallback asyncCallback, Object asyncState)
InnerException : System.Data.SqlClient.SqlException (0x80131904): A network-related or instance-specific error occurred while establishing a connection to SQL Server. The server was not found or was not accessible. Verify that the instance name is correct and that SQL Server is configured to allow remote connections. (provider: Named Pipes Provider, error: 40 - Could not open a connection to SQL Server) ---> System.ComponentModel.Win32Exception (0x80004005): The network path was not found
   at System.Data.ProviderBase.DbConnectionPool.TryGetConnection(DbConnection owningObject, UInt32 waitForMultipleObjectsTimeout, Boolean allowCreate, Boolean onlyOneCheckConnection, DbConnectionOptions userOptions, DbConnectionInternal& connection)
   at System.Data.ProviderBase.DbConnectionPool.TryGetConnection(DbConnection owningObject, TaskCompletionSource`1 retry, DbConnectionOptions userOptions, DbConnectionInternal& connection)
   at System.Data.ProviderBase.DbConnectionFactory.TryGetConnection(DbConnection owningConnection, TaskCompletionSource`1 retry, DbConnectionOptions userOptions, DbConnectionInternal oldConnection, DbConnectionInternal& connection)
   at System.Data.ProviderBase.DbConnectionInternal.TryOpenConnectionInternal(DbConnection outerConnection, DbConnectionFactory connectionFactory, TaskCompletionSource`1 retry, DbConnectionOptions userOptions)
   at System.Data.SqlClient.SqlConnection.TryOpenInner(TaskCompletionSource`1 retry)
   at System.Data.SqlClient.SqlConnection.TryOpen(TaskCompletionSource`1 retry)
   at System.Data.SqlClient.SqlConnection.Open()
   at System.Data.Entity.Infrastructure.Interception.InternalDispatcher`1.Dispatch[TTarget,TInterceptionContext](TTarget target, Action`2 operation, TInterceptionContext interceptionContext, Action`3 executing, Action`3 executed)
   at System.Data.Entity.Infrastructure.Interception.DbConnectionDispatcher.Open(DbConnection connection, DbInterceptionContext interceptionContext)
   at System.Data.Entity.SqlServer.DefaultSqlExecutionStrategy.<>c__DisplayClass1.<Execute>b__0()
   at System.Data.Entity.SqlServer.DefaultSqlExecutionStrategy.Execute[TResult](Func`1 operation)
   at System.Data.Entity.Core.EntityClient.EntityConnection.Open()
ClientConnectionId:00000000-0000-0000-0000-000000000000
Error Number:53,State:0,Class:20
GetBaseException : System.ComponentModel.Win32Exception (0x80004005): The network path was not found
TargetSite : Void Open()
